Unable to init server: Could not connect: Connection refused
Unable to init server: Could not connect: Connection refused
Unable to init server: Could not connect: Connection refused
Unable to init server: Could not connect: Connection refused

(DataCollector_Deterministic.py:3317803): Gdk-CRITICAL **: 00:59:42.537: gdk_cursor_new_for_display: assertion 'GDK_IS_DISPLAY (display)' failed
Unable to init server: Could not connect: Connection refused
Unable to init server: Could not connect: Connection refused

(DataCollector_Deterministic.py:3317821): Gdk-CRITICAL **: 00:59:42.611: gdk_cursor_new_for_display: assertion 'GDK_IS_DISPLAY (display)' failed
Unable to init server: Could not connect: Connection refused

(DataCollector_Deterministic.py:3317760): Gdk-CRITICAL **: 00:59:42.632: gdk_cursor_new_for_display: assertion 'GDK_IS_DISPLAY (display)' failed
Unable to init server: Could not connect: Connection refused

(DataCollector_Deterministic.py:3317839): Gdk-CRITICAL **: 00:59:42.728: gdk_cursor_new_for_display: assertion 'GDK_IS_DISPLAY (display)' failed
Unable to init server: Could not connect: Connection refused
Unable to init server: Could not connect: Connection refused
Unable to init server: Could not connect: Connection refused
Unable to init server: Could not connect: Connection refused
Unable to init server: Could not connect: Connection refused
Unable to init server: Could not connect: Connection refused
Unable to init server: Could not connect: Connection refused
Unable to init server: Could not connect: Connection refused

(DataCollector_Deterministic.py:3317783): Gdk-CRITICAL **: 00:59:42.900: gdk_cursor_new_for_display: assertion 'GDK_IS_DISPLAY (display)' failed

(DataCollector_Deterministic.py:3317877): Gdk-CRITICAL **: 00:59:42.904: gdk_cursor_new_for_display: assertion 'GDK_IS_DISPLAY (display)' failed
Unable to init server: Could not connect: Connection refused

(DataCollector_Deterministic.py:3317855): Gdk-CRITICAL **: 00:59:42.917: gdk_cursor_new_for_display: assertion 'GDK_IS_DISPLAY (display)' failed
Unable to init server: Could not connect: Connection refused

(DataCollector_Deterministic.py:3317899): Gdk-CRITICAL **: 00:59:42.921: gdk_cursor_new_for_display: assertion 'GDK_IS_DISPLAY (display)' failed
Unable to init server: Could not connect: Connection refused

(DataCollector_Deterministic.py:3317758): Gdk-CRITICAL **: 00:59:42.926: gdk_cursor_new_for_display: assertion 'GDK_IS_DISPLAY (display)' failed
Unable to init server: Could not connect: Connection refused

(DataCollector_Deterministic.py:3317907): Gdk-CRITICAL **: 00:59:42.994: gdk_cursor_new_for_display: assertion 'GDK_IS_DISPLAY (display)' failed
Initalising...
Running Sim...
.Initalising...
Running Sim...
.Initalising...
Running Sim...
.Initalising...
Running Sim...
.Initalising...
Running Sim...
.Initalising...
Running Sim...
.Initalising...
Running Sim...
.Initalising...
Running Sim...
.Initalising...
Running Sim...
.Initalising...
Running Sim...
...........................................................................................
[4761 9594]
.
[4666 9600]
.
[4681 9594]
.
[4608 9621]
.
[4687 9627]
.
[4701 9640]
.
[4688 9610]
.
[4713 9633]
.
[4692 9614]
.
[4710 9635]
...........................................................................................
[2261 9173]
.
[2326 9198]
.
[2255 9196]
.
[2301 9224]
.
[2302 9176]
.
[2266 9246]
.
[2234 9231]
.
[2285 9221]
.
[2281 9238]
.
[2252 9218]
...........................................................................................
[1118 8743]
.
[1195 8799]
.
[1155 8775]
.
[1117 8841]
.
[1129 8844]
.
[1115 8843]
.
[1106 8771]
.
[1139 8824]
.
[1163 8852]
.
[1150 8830]
..........................................................................................
[ 611 8314]
..
[ 612 8378]
.
[ 626 8363]
.
[ 580 8428]
.
[ 637 8375]
.
[ 598 8443]
.
[ 607 8434]
.
[ 587 8404]
.
[ 625 8431]
..
[ 614 8430]
......................................................................................
[ 347 7915]
....
[ 340 7961]
.
[ 350 7901]
..
[ 344 8028]
.
[ 350 7911]
.
[ 350 8013]
..
[ 316 7988]
.
[ 339 7988]
.
[ 344 8036]
...
[ 358 8029]
................................................................................
[ 227 7485]
......
[ 209 7543]
....
[ 227 7388]
.
[ 212 7576]
.
[ 234 7516]
..
[ 220 7618]
.
[ 189 7560]
..
[ 202 7644]
...
[ 195 7328]
...
[ 210 7614]
...................................................................
[ 144 7055]
.............
[ 136 7051]
...
[ 122 7168]
.
[ 158 7036]
...
[ 146 7204]
.....
[ 152 6632]
....
[ 122 7133]
...
[ 122 7206]
.
[ 145 7199]
...............
[ 123 6016]
............................................
[  95 6635]
.............
[  96 6604]
....
[  82 6731]
...
[ 117 6494]
....
[ 102 6786]
.........
[  87 6710]
....
[ 102 6737]
..
[  85 6789]
...............
[ 120 5486]
................................
[  73 6223]
..............
[  77 6063]
..
[  64 6298]
.........
[ 109 4135]
.....
[  70 6358]
.....
[  89 5703]
........
[  69 6301]
....
[  76 6311]
..........
[  65 6363]
......................
[  62 5812]
...................
[  66 5455]
..
[  54 5861]
...............
[  99 4161]
.....
[  60 5915]
..........
[  45 5870]
.........
[  61 5875]
...........
[  55 5348]
.....
[  53 5844]
....
[  71 4571]
...................
[  48 5440]
...............
[  54 4570]
...........
[  47 5412]
.......
[  51 4943]
.....
[  40 5432]
.........
[  52 5471]
....................
[  46 5022]
.............
[  49 5179]
.....
[  92 2588]
.....................
[  44 4617]
.
[  35 5012]
...
[  45 4609]
../home/s1932078/Documents/MPhys_Project/SRI/src/data_extraction/DataCollector_Deterministic.py:120: UserWarning: Creating legend with loc="best" can be slow with large amounts of data.
  plt.savefig(os.path.join(data_output_path, f'InfectionsVsTimePlot_{name_suffix}.png'))

Data Dump...
...
[  48 5032]
......
[  49 3382]
..............
[  64 3263]
.........
[  85 2863]
.../home/s1932078/Documents/MPhys_Project/SRI/src/data_extraction/DataCollector_Deterministic.py:120: UserWarning: Creating legend with loc="best" can be slow with large amounts of data.
  plt.savefig(os.path.join(data_output_path, f'InfectionsVsTimePlot_{name_suffix}.png'))

[  35 4537]

Data Dump...
....../home/s1932078/Documents/MPhys_Project/SRI/src/data_extraction/DataCollector_Deterministic.py:120: UserWarning: Creating legend with loc="best" can be slow with large amounts of data.
  plt.savefig(os.path.join(data_output_path, f'InfectionsVsTimePlot_{name_suffix}.png'))

[  48 4566]

Data Dump...
..........
[  48 4017]
...
[  40 3121]
..................
[  48 2335]
.......................
[  37 1924]
.....
[  45 2616]
.
[  59 2135]
...............
[  45 1488]
...............
[  77 1854]
..
[  75 1603]
.....
[  35 1201]
...........
[  41 1613]
......
[ 40 959]
....................
[  54 1420]
........
[ 35 767]
.......
[ 37 681]
.............
[  41 1047]
...............
[ 33 534]
....../home/s1932078/Documents/MPhys_Project/SRI/src/data_extraction/DataCollector_Deterministic.py:120: UserWarning: Creating legend with loc="best" can be slow with large amounts of data.
  plt.savefig(os.path.join(data_output_path, f'InfectionsVsTimePlot_{name_suffix}.png'))

Data Dump...
...
[ 31 569]
..........
[  69 1201]
.............
[ 39 739]
.
[ 49 921]
.
[ 28 433]
................./home/s1932078/Documents/MPhys_Project/SRI/src/data_extraction/DataCollector_Deterministic.py:120: UserWarning: Creating legend with loc="best" can be slow with large amounts of data.
  plt.savefig(os.path.join(data_output_path, f'InfectionsVsTimePlot_{name_suffix}.png'))

Data Dump...
....
[  69 1007]
.......
[ 36 539]
...................
[ 33 446]
..
[ 45 622]
........./home/s1932078/Documents/MPhys_Project/SRI/src/data_extraction/DataCollector_Deterministic.py:120: UserWarning: Creating legend with loc="best" can be slow with large amounts of data.
  plt.savefig(os.path.join(data_output_path, f'InfectionsVsTimePlot_{name_suffix}.png'))

Data Dump...
....
[ 60 793]
............
[ 40 443]
..................
[ 63 653]
.
[ 37 316]
......
[ 56 566]
..........
[ 34 266]
...............
[ 29 233]
...../home/s1932078/Documents/MPhys_Project/SRI/src/data_extraction/DataCollector_Deterministic.py:120: UserWarning: Creating legend with loc="best" can be slow with large amounts of data.
  plt.savefig(os.path.join(data_output_path, f'InfectionsVsTimePlot_{name_suffix}.png'))

Data Dump...
.....
[ 54 425]
..........
[ 60 423]
.....
[ 52 308]
...............
[ 48 252]
.............
[ 45 222]
.
[ 54 303]
............
[ 39 197]
............
[ 37 182]
...../home/s1932078/Documents/MPhys_Project/SRI/src/data_extraction/DataCollector_Deterministic.py:120: UserWarning: Creating legend with loc="best" can be slow with large amounts of data.
  plt.savefig(os.path.join(data_output_path, f'InfectionsVsTimePlot_{name_suffix}.png'))

Data Dump...
....
[ 52 224]
..........
[ 51 154]
..........
[ 46 119]
..........
[ 42 103]
..........
[40 91]
..........
[38 81]
..........
[35 77]
..........
[34 72]
..........
[27 66]
..........
[26 64]
..........
[26 63]
..../home/s1932078/Documents/MPhys_Project/SRI/src/data_extraction/DataCollector_Deterministic.py:120: UserWarning: Creating legend with loc="best" can be slow with large amounts of data.
  plt.savefig(os.path.join(data_output_path, f'InfectionsVsTimePlot_{name_suffix}.png'))

Data Dump...
High 1 5
Done
slurmstepd-phcompute025: error: Detected 1 oom-kill event(s) in StepId=810624.batch. Some of your processes may have been killed by the cgroup out-of-memory handler.
