Unable to init server: Could not connect: Connection refused
Unable to init server: Could not connect: Connection refused
Unable to init server: Could not connect: Connection refused
Unable to init server: Could not connect: Connection refused
Unable to init server: Could not connect: Connection refused
Unable to init server: Could not connect: Connection refused
Unable to init server: Could not connect: Connection refused
Unable to init server: Could not connect: Connection refused
Unable to init server: Could not connect: Connection refused
Unable to init server: Could not connect: Connection refused
Unable to init server: Could not connect: Connection refused
Unable to init server: Could not connect: Connection refused
Unable to init server: Could not connect: Connection refused
Unable to init server: Could not connect: Connection refused

(DataCollector_Deterministic.py:3813334): Gdk-CRITICAL **: 08:13:51.459: gdk_cursor_new_for_display: assertion 'GDK_IS_DISPLAY (display)' failed
Unable to init server: Could not connect: Connection refused
Unable to init server: Could not connect: Connection refused

(DataCollector_Deterministic.py:3813725): Gdk-CRITICAL **: 08:13:51.473: gdk_cursor_new_for_display: assertion 'GDK_IS_DISPLAY (display)' failed
Unable to init server: Could not connect: Connection refused

(DataCollector_Deterministic.py:3814729): Gdk-CRITICAL **: 08:13:51.475: gdk_cursor_new_for_display: assertion 'GDK_IS_DISPLAY (display)' failed
Unable to init server: Could not connect: Connection refused
Unable to init server: Could not connect: Connection refused

(DataCollector_Deterministic.py:3814195): Gdk-CRITICAL **: 08:13:51.517: gdk_cursor_new_for_display: assertion 'GDK_IS_DISPLAY (display)' failed
Unable to init server: Could not connect: Connection refused

(DataCollector_Deterministic.py:3814251): Gdk-CRITICAL **: 08:13:51.557: gdk_cursor_new_for_display: assertion 'GDK_IS_DISPLAY (display)' failed
Unable to init server: Could not connect: Connection refused
Unable to init server: Could not connect: Connection refused

(DataCollector_Deterministic.py:3813702): Gdk-CRITICAL **: 08:13:51.585: gdk_cursor_new_for_display: assertion 'GDK_IS_DISPLAY (display)' failed
Unable to init server: Could not connect: Connection refused
Unable to init server: Could not connect: Connection refused
Unable to init server: Could not connect: Connection refused
Unable to init server: Could not connect: Connection refused
Unable to init server: Could not connect: Connection refused
Unable to init server: Could not connect: Connection refused

(DataCollector_Deterministic.py:3815075): Gdk-CRITICAL **: 08:13:51.752: gdk_cursor_new_for_display: assertion 'GDK_IS_DISPLAY (display)' failed
Unable to init server: Could not connect: Connection refused

(DataCollector_Deterministic.py:3814312): Gdk-CRITICAL **: 08:13:51.765: gdk_cursor_new_for_display: assertion 'GDK_IS_DISPLAY (display)' failed
Unable to init server: Could not connect: Connection refused

(DataCollector_Deterministic.py:3815120): Gdk-CRITICAL **: 08:13:51.768: gdk_cursor_new_for_display: assertion 'GDK_IS_DISPLAY (display)' failed
Unable to init server: Could not connect: Connection refused

(DataCollector_Deterministic.py:3813922): Gdk-CRITICAL **: 08:13:51.836: gdk_cursor_new_for_display: assertion 'GDK_IS_DISPLAY (display)' failed
Unable to init server: Could not connect: Connection refused
Unable to init server: Could not connect: Connection refused

(DataCollector_Deterministic.py:3813149): Gdk-CRITICAL **: 08:13:51.893: gdk_cursor_new_for_display: assertion 'GDK_IS_DISPLAY (display)' failed
Unable to init server: Could not connect: Connection refused

(DataCollector_Deterministic.py:3813308): Gdk-CRITICAL **: 08:13:51.897: gdk_cursor_new_for_display: assertion 'GDK_IS_DISPLAY (display)' failed

(DataCollector_Deterministic.py:3813872): Gdk-CRITICAL **: 08:13:51.904: gdk_cursor_new_for_display: assertion 'GDK_IS_DISPLAY (display)' failed
Unable to init server: Could not connect: Connection refused

(DataCollector_Deterministic.py:3813850): Gdk-CRITICAL **: 08:13:51.916: gdk_cursor_new_for_display: assertion 'GDK_IS_DISPLAY (display)' failed
Unable to init server: Could not connect: Connection refused

(DataCollector_Deterministic.py:3814855): Gdk-CRITICAL **: 08:13:51.945: gdk_cursor_new_for_display: assertion 'GDK_IS_DISPLAY (display)' failed
Unable to init server: Could not connect: Connection refused
Unable to init server: Could not connect: Connection refused

(DataCollector_Deterministic.py:3814006): Gdk-CRITICAL **: 08:13:51.986: gdk_cursor_new_for_display: assertion 'GDK_IS_DISPLAY (display)' failed
Unable to init server: Could not connect: Connection refused

(DataCollector_Deterministic.py:3814945): Gdk-CRITICAL **: 08:13:51.995: gdk_cursor_new_for_display: assertion 'GDK_IS_DISPLAY (display)' failed
Unable to init server: Could not connect: Connection refused

(DataCollector_Deterministic.py:3813485): Gdk-CRITICAL **: 08:13:52.005: gdk_cursor_new_for_display: assertion 'GDK_IS_DISPLAY (display)' failed

(DataCollector_Deterministic.py:3814748): Gdk-CRITICAL **: 08:13:52.020: gdk_cursor_new_for_display: assertion 'GDK_IS_DISPLAY (display)' failed
Traceback (most recent call last):
  File "/usr/lib/python3.8/runpy.py", line 194, in _run_module_as_main
    return _run_code(code, main_globals, None,
  File "/usr/lib/python3.8/runpy.py", line 87, in _run_code
    exec(code, run_globals)
  File "/home/s1932078/Documents/MPhys_Project/SRI/src/data_extraction/DataCollector_Deterministic.py", line 24, in <module>
    execute = SIR(config_file=config_file_path)
  File "/home/s1932078/Documents/MPhys_Project/SRI/src/simulation/SIR_system.py", line 101, in __init__
    self.all_current_nbs = self.network_matrix()
  File "/home/s1932078/Documents/MPhys_Project/SRI/src/simulation/SIR_system.py", line 124, in network_matrix
    sparse = nx.to_scipy_sparse_array(self.G, format='csr')
  File "/home/s1932078/.local/lib/python3.8/site-packages/networkx/convert_matrix.py", line 593, in to_scipy_sparse_array
    A = sp.sparse.coo_array((d, (r, c)), shape=(nlen, nlen), dtype=dtype)
AttributeError: module 'scipy.sparse' has no attribute 'coo_array'
Initalising...
Traceback (most recent call last):
  File "/usr/lib/python3.8/runpy.py", line 194, in _run_module_as_main
    return _run_code(code, main_globals, None,
  File "/usr/lib/python3.8/runpy.py", line 87, in _run_code
    exec(code, run_globals)
  File "/home/s1932078/Documents/MPhys_Project/SRI/src/data_extraction/DataCollector_Deterministic.py", line 24, in <module>
    execute = SIR(config_file=config_file_path)
  File "/home/s1932078/Documents/MPhys_Project/SRI/src/simulation/SIR_system.py", line 101, in __init__
    self.all_current_nbs = self.network_matrix()
  File "/home/s1932078/Documents/MPhys_Project/SRI/src/simulation/SIR_system.py", line 124, in network_matrix
    sparse = nx.to_scipy_sparse_array(self.G, format='csr')
  File "/home/s1932078/.local/lib/python3.8/site-packages/networkx/convert_matrix.py", line 593, in to_scipy_sparse_array
    A = sp.sparse.coo_array((d, (r, c)), shape=(nlen, nlen), dtype=dtype)
AttributeError: module 'scipy.sparse' has no attribute 'coo_array'
Initalising...
Traceback (most recent call last):
  File "/usr/lib/python3.8/runpy.py", line 194, in _run_module_as_main
    return _run_code(code, main_globals, None,
  File "/usr/lib/python3.8/runpy.py", line 87, in _run_code
    exec(code, run_globals)
  File "/home/s1932078/Documents/MPhys_Project/SRI/src/data_extraction/DataCollector_Deterministic.py", line 24, in <module>
    execute = SIR(config_file=config_file_path)
  File "/home/s1932078/Documents/MPhys_Project/SRI/src/simulation/SIR_system.py", line 101, in __init__
    self.all_current_nbs = self.network_matrix()
  File "/home/s1932078/Documents/MPhys_Project/SRI/src/simulation/SIR_system.py", line 124, in network_matrix
    sparse = nx.to_scipy_sparse_array(self.G, format='csr')
  File "/home/s1932078/.local/lib/python3.8/site-packages/networkx/convert_matrix.py", line 593, in to_scipy_sparse_array
    A = sp.sparse.coo_array((d, (r, c)), shape=(nlen, nlen), dtype=dtype)
AttributeError: module 'scipy.sparse' has no attribute 'coo_array'
Initalising...
Traceback (most recent call last):
  File "/usr/lib/python3.8/runpy.py", line 194, in _run_module_as_main
    return _run_code(code, main_globals, None,
  File "/usr/lib/python3.8/runpy.py", line 87, in _run_code
    exec(code, run_globals)
  File "/home/s1932078/Documents/MPhys_Project/SRI/src/data_extraction/DataCollector_Deterministic.py", line 24, in <module>
    execute = SIR(config_file=config_file_path)
  File "/home/s1932078/Documents/MPhys_Project/SRI/src/simulation/SIR_system.py", line 101, in __init__
    self.all_current_nbs = self.network_matrix()
  File "/home/s1932078/Documents/MPhys_Project/SRI/src/simulation/SIR_system.py", line 124, in network_matrix
    sparse = nx.to_scipy_sparse_array(self.G, format='csr')
  File "/home/s1932078/.local/lib/python3.8/site-packages/networkx/convert_matrix.py", line 593, in to_scipy_sparse_array
    A = sp.sparse.coo_array((d, (r, c)), shape=(nlen, nlen), dtype=dtype)
AttributeError: module 'scipy.sparse' has no attribute 'coo_array'
Initalising...
Traceback (most recent call last):
  File "/usr/lib/python3.8/runpy.py", line 194, in _run_module_as_main
    return _run_code(code, main_globals, None,
  File "/usr/lib/python3.8/runpy.py", line 87, in _run_code
    exec(code, run_globals)
  File "/home/s1932078/Documents/MPhys_Project/SRI/src/data_extraction/DataCollector_Deterministic.py", line 24, in <module>
    execute = SIR(config_file=config_file_path)
  File "/home/s1932078/Documents/MPhys_Project/SRI/src/simulation/SIR_system.py", line 101, in __init__
    self.all_current_nbs = self.network_matrix()
  File "/home/s1932078/Documents/MPhys_Project/SRI/src/simulation/SIR_system.py", line 124, in network_matrix
    sparse = nx.to_scipy_sparse_array(self.G, format='csr')
  File "/home/s1932078/.local/lib/python3.8/site-packages/networkx/convert_matrix.py", line 593, in to_scipy_sparse_array
    A = sp.sparse.coo_array((d, (r, c)), shape=(nlen, nlen), dtype=dtype)
AttributeError: module 'scipy.sparse' has no attribute 'coo_array'
Initalising...
Traceback (most recent call last):
  File "/usr/lib/python3.8/runpy.py", line 194, in _run_module_as_main
    return _run_code(code, main_globals, None,
  File "/usr/lib/python3.8/runpy.py", line 87, in _run_code
    exec(code, run_globals)
  File "/home/s1932078/Documents/MPhys_Project/SRI/src/data_extraction/DataCollector_Deterministic.py", line 24, in <module>
    execute = SIR(config_file=config_file_path)
  File "/home/s1932078/Documents/MPhys_Project/SRI/src/simulation/SIR_system.py", line 101, in __init__
    self.all_current_nbs = self.network_matrix()
  File "/home/s1932078/Documents/MPhys_Project/SRI/src/simulation/SIR_system.py", line 124, in network_matrix
    sparse = nx.to_scipy_sparse_array(self.G, format='csr')
  File "/home/s1932078/.local/lib/python3.8/site-packages/networkx/convert_matrix.py", line 593, in to_scipy_sparse_array
    A = sp.sparse.coo_array((d, (r, c)), shape=(nlen, nlen), dtype=dtype)
AttributeError: module 'scipy.sparse' has no attribute 'coo_array'
Initalising...
Traceback (most recent call last):
  File "/usr/lib/python3.8/runpy.py", line 194, in _run_module_as_main
    return _run_code(code, main_globals, None,
  File "/usr/lib/python3.8/runpy.py", line 87, in _run_code
    exec(code, run_globals)
  File "/home/s1932078/Documents/MPhys_Project/SRI/src/data_extraction/DataCollector_Deterministic.py", line 24, in <module>
    execute = SIR(config_file=config_file_path)
  File "/home/s1932078/Documents/MPhys_Project/SRI/src/simulation/SIR_system.py", line 101, in __init__
    self.all_current_nbs = self.network_matrix()
  File "/home/s1932078/Documents/MPhys_Project/SRI/src/simulation/SIR_system.py", line 124, in network_matrix
    sparse = nx.to_scipy_sparse_array(self.G, format='csr')
  File "/home/s1932078/.local/lib/python3.8/site-packages/networkx/convert_matrix.py", line 593, in to_scipy_sparse_array
    A = sp.sparse.coo_array((d, (r, c)), shape=(nlen, nlen), dtype=dtype)
AttributeError: module 'scipy.sparse' has no attribute 'coo_array'
Initalising...
Traceback (most recent call last):
  File "/usr/lib/python3.8/runpy.py", line 194, in _run_module_as_main
    return _run_code(code, main_globals, None,
  File "/usr/lib/python3.8/runpy.py", line 87, in _run_code
    exec(code, run_globals)
  File "/home/s1932078/Documents/MPhys_Project/SRI/src/data_extraction/DataCollector_Deterministic.py", line 24, in <module>
    execute = SIR(config_file=config_file_path)
  File "/home/s1932078/Documents/MPhys_Project/SRI/src/simulation/SIR_system.py", line 101, in __init__
    self.all_current_nbs = self.network_matrix()
  File "/home/s1932078/Documents/MPhys_Project/SRI/src/simulation/SIR_system.py", line 124, in network_matrix
    sparse = nx.to_scipy_sparse_array(self.G, format='csr')
  File "/home/s1932078/.local/lib/python3.8/site-packages/networkx/convert_matrix.py", line 593, in to_scipy_sparse_array
    A = sp.sparse.coo_array((d, (r, c)), shape=(nlen, nlen), dtype=dtype)
AttributeError: module 'scipy.sparse' has no attribute 'coo_array'
Initalising...
Traceback (most recent call last):
  File "/usr/lib/python3.8/runpy.py", line 194, in _run_module_as_main
    return _run_code(code, main_globals, None,
  File "/usr/lib/python3.8/runpy.py", line 87, in _run_code
    exec(code, run_globals)
  File "/home/s1932078/Documents/MPhys_Project/SRI/src/data_extraction/DataCollector_Deterministic.py", line 24, in <module>
    execute = SIR(config_file=config_file_path)
  File "/home/s1932078/Documents/MPhys_Project/SRI/src/simulation/SIR_system.py", line 101, in __init__
    self.all_current_nbs = self.network_matrix()
  File "/home/s1932078/Documents/MPhys_Project/SRI/src/simulation/SIR_system.py", line 124, in network_matrix
    sparse = nx.to_scipy_sparse_array(self.G, format='csr')
  File "/home/s1932078/.local/lib/python3.8/site-packages/networkx/convert_matrix.py", line 593, in to_scipy_sparse_array
    A = sp.sparse.coo_array((d, (r, c)), shape=(nlen, nlen), dtype=dtype)
AttributeError: module 'scipy.sparse' has no attribute 'coo_array'
Initalising...
No 1 6
Done
slurmstepd-phcompute025: error: Detected 91 oom-kill event(s) in StepId=824501.batch. Some of your processes may have been killed by the cgroup out-of-memory handler.
