Unable to init server: Could not connect: Connection refused
Unable to init server: Could not connect: Connection refused
Unable to init server: Could not connect: Connection refused
Unable to init server: Could not connect: Connection refused
Unable to init server: Could not connect: Connection refused

(DataCollector_Deterministic.py:4121847): Gdk-CRITICAL **: 01:01:00.780: gdk_cursor_new_for_display: assertion 'GDK_IS_DISPLAY (display)' failed
Unable to init server: Could not connect: Connection refused
Unable to init server: Could not connect: Connection refused

(DataCollector_Deterministic.py:4121853): Gdk-CRITICAL **: 01:01:00.844: gdk_cursor_new_for_display: assertion 'GDK_IS_DISPLAY (display)' failed
Unable to init server: Could not connect: Connection refused
Unable to init server: Could not connect: Connection refused

(DataCollector_Deterministic.py:4121898): Gdk-CRITICAL **: 01:01:00.882: gdk_cursor_new_for_display: assertion 'GDK_IS_DISPLAY (display)' failed
Unable to init server: Could not connect: Connection refused
Unable to init server: Could not connect: Connection refused
Unable to init server: Could not connect: Connection refused

(DataCollector_Deterministic.py:4121871): Gdk-CRITICAL **: 01:01:00.911: gdk_cursor_new_for_display: assertion 'GDK_IS_DISPLAY (display)' failed
Unable to init server: Could not connect: Connection refused
Unable to init server: Could not connect: Connection refused
Unable to init server: Could not connect: Connection refused

(DataCollector_Deterministic.py:4121919): Gdk-CRITICAL **: 01:01:00.993: gdk_cursor_new_for_display: assertion 'GDK_IS_DISPLAY (display)' failed
Unable to init server: Could not connect: Connection refused

(DataCollector_Deterministic.py:4121938): Gdk-CRITICAL **: 01:01:01.016: gdk_cursor_new_for_display: assertion 'GDK_IS_DISPLAY (display)' failed
Unable to init server: Could not connect: Connection refused

(DataCollector_Deterministic.py:4121985): Gdk-CRITICAL **: 01:01:01.089: gdk_cursor_new_for_display: assertion 'GDK_IS_DISPLAY (display)' failed
Unable to init server: Could not connect: Connection refused

(DataCollector_Deterministic.py:4121967): Gdk-CRITICAL **: 01:01:01.098: gdk_cursor_new_for_display: assertion 'GDK_IS_DISPLAY (display)' failed
Unable to init server: Could not connect: Connection refused

(DataCollector_Deterministic.py:4122001): Gdk-CRITICAL **: 01:01:01.145: gdk_cursor_new_for_display: assertion 'GDK_IS_DISPLAY (display)' failed
Unable to init server: Could not connect: Connection refused

(DataCollector_Deterministic.py:4122014): Gdk-CRITICAL **: 01:01:01.163: gdk_cursor_new_for_display: assertion 'GDK_IS_DISPLAY (display)' failed
Initalising...
Running Sim...
.Initalising...
Running Sim...
.Initalising...
Running Sim...
.Initalising...
Running Sim...
.Initalising...
Running Sim...
.Initalising...
Running Sim...
.Initalising...
Running Sim...
.Initalising...
Running Sim...
.Initalising...
Running Sim...
.Initalising...
Running Sim...
...........................................................................................
[4732 9417]
.
[4724 9450]
.
[4752 9379]
.
[4742 9453]
.
[4753 9426]
.
[4666 9485]
.
[4698 9478]
.
[4672 9502]
.
[5105 8638]
......
[7159 6202]
.................................................................................
[2312 8890]
.
[2277 8903]
...
[2275 8854]
.
[2244 8931]
.
[2271 8934]
.
[2310 8804]
.
[2250 8683]
.
[2250 8902]
...................
[3273 6080]
.............
[5998 3304]
.....................................................
[1167 8357]
.
[1157 8331]
...
[1115 8243]
.
[1157 8345]
.
[1100 8366]
.
[1186 8033]
.
[1134 8357]
....
[1132 7741]
.......................................................
[2381 3888]
......................
[5120 1736]
..
[ 644 7782]
.
[ 613 7719]
....
[ 605 7805]
.
[ 595 7770]
.
[ 595 7511]
.
[ 605 7803]
....
[ 672 7149]
............
[ 637 6516]
..............................................................
[ 348 7150]
..
[ 367 7198]
.....
[ 326 7163]
.
[ 328 7247]
...
[ 336 6830]
.
[ 338 7173]
............
[ 400 6102]
........................
[1779 2427]
.....
[ 397 5197]
...............
[4332  979]
.................
[ 200 6550]
...
[ 226 6597]
...
[ 182 6626]
....
[ 189 6665]
..
[ 208 6575]
...
[ 206 6039]
..............................
[ 247 5021]
....................................
[ 124 5985]
.
[ 135 5999]
....
[ 125 6022]
.......
[ 128 6074]
.
[ 140 5954]
...
[ 277 3866]
.........
[ 152 5202]
...........................................
[1396 1508]
..........
[  81 5402]
.
[ 103 5405]
...
[ 178 3907]
.
[  81 5461]
....
[ 101 5326]
.
[  94 5446]
......
[3633  564]
.............................
[ 102 4304]
..........................
[  74 4802]
......
[  57 4810]
....
[  73 4724]
.
[  57 4864]
......
[  72 4906]
.....
[ 193 2761]
.................................................
[  69 4222]
..
[  54 4113]
..
[ 139 2934]
....
[  82 3393]
.
[  48 4193]
...
[  45 4260]
........
[  54 4301]
............................................
[  55 3637]
...
[  46 3515]
..............
[  38 3674]
.
[  39 3500]
........
[  49 3715]
.................
[1076  927]
................
[  43 2918]
.....
[  48 3048]
......
[  65 2546]
........
[  35 3052]
...........
[3003  336]
....
[  38 2830]
....
[  47 3145]
..........
[ 149 1887]
.......
[  44 2432]
......../home/s1932078/Documents/MPhys_Project/SRI/src/data_extraction/DataCollector_Deterministic.py:120: UserWarning: Creating legend with loc="best" can be slow with large amounts of data.
  plt.savefig(os.path.join(data_output_path, f'InfectionsVsTimePlot_{name_suffix}.png'))

Data Dump...
/home/s1932078/Documents/MPhys_Project/SRI/src/data_extraction/DataCollector_Deterministic.py:120: UserWarning: Creating legend with loc="best" can be slow with large amounts of data.
  plt.savefig(os.path.join(data_output_path, f'InfectionsVsTimePlot_{name_suffix}.png'))

[  33 2401]

Data Dump...
...........
[ 109 2158]
...
[  46 2538]
..../home/s1932078/Documents/MPhys_Project/SRI/src/data_extraction/DataCollector_Deterministic.py:120: UserWarning: Creating legend with loc="best" can be slow with large amounts of data.
  plt.savefig(os.path.join(data_output_path, f'InfectionsVsTimePlot_{name_suffix}.png'))

Data Dump...

[  38 2059]
...................
[  36 1458]
......../home/s1932078/Documents/MPhys_Project/SRI/src/data_extraction/DataCollector_Deterministic.py:120: UserWarning: Creating legend with loc="best" can be slow with large amounts of data.
  plt.savefig(os.path.join(data_output_path, f'InfectionsVsTimePlot_{name_suffix}.png'))

Data Dump...

[  57 1839]
...........................
[  51 1331]
..
[  93 1533]
........
[ 123 1335]
.............
[ 44 957]
.
[833 600]
............
[2473  215]
......
[ 41 684]
............/home/s1932078/Documents/MPhys_Project/SRI/src/data_extraction/DataCollector_Deterministic.py:120: UserWarning: Creating legend with loc="best" can be slow with large amounts of data.
  plt.savefig(os.path.join(data_output_path, f'InfectionsVsTimePlot_{name_suffix}.png'))

Data Dump...
.
[  76 1059]
..............
[ 96 915]
..........
[ 64 760]
....................
[660 380]
...
[ 56 542]
......
[ 91 641]
..
[2045  139]
.............
[ 50 391]
.................
[ 44 297]
........../home/s1932078/Documents/MPhys_Project/SRI/src/data_extraction/DataCollector_Deterministic.py:120: UserWarning: Creating legend with loc="best" can be slow with large amounts of data.
  plt.savefig(os.path.join(data_output_path, f'InfectionsVsTimePlot_{name_suffix}.png'))

Data Dump...
..
[ 81 460]
..............
[528 261]
.....
[ 73 330]
.....
[1678   86]
............
[ 62 254]
...............
[ 55 192]
..............
[ 43 150]
.
[424 187]
......../home/s1932078/Documents/MPhys_Project/SRI/src/data_extraction/DataCollector_Deterministic.py:120: UserWarning: Creating legend with loc="best" can be slow with large amounts of data.
  plt.savefig(os.path.join(data_output_path, f'InfectionsVsTimePlot_{name_suffix}.png'))

Data Dump...
.....
[1330   60]
............
[345 132]
..........
[1043   49]
........
[285 104]
..............
[831  36]
....
[241  80]
..................
[205  65]
.
[684  25]
................
[172  54]
........
[551  21]
.........
[150  44]
................
[457  17]
.
[120  37]
...............
[102  35]
............
[391  14]
....
[85 28]
..............
[68 26]
..............
[62 26]
....
[318  13]
........
[51 25]
.............
[45 23]
./home/s1932078/Documents/MPhys_Project/SRI/src/data_extraction/DataCollector_Deterministic.py:120: UserWarning: Creating legend with loc="best" can be slow with large amounts of data.
  plt.savefig(os.path.join(data_output_path, f'InfectionsVsTimePlot_{name_suffix}.png'))

Data Dump...
.....
[268  11]
..........
[223  10]
..........
[192  10]
..........
[164  10]
..........
[141  10]
..........
[114  10]
..........
[95 10]
..........
[80 10]
..........
[68 10]
......../home/s1932078/Documents/MPhys_Project/SRI/src/data_extraction/DataCollector_Deterministic.py:120: UserWarning: Creating legend with loc="best" can be slow with large amounts of data.
  plt.savefig(os.path.join(data_output_path, f'InfectionsVsTimePlot_{name_suffix}.png'))

Data Dump...
Low 1 7
Done
slurmstepd-phcompute006: error: Detected 1 oom-kill event(s) in StepId=810636.batch. Some of your processes may have been killed by the cgroup out-of-memory handler.
